Workbook

Sheet Summary
A1: Change Log
A2: Change | B2: Date | C2: Note
A3: Add band related logs | B3: 46282
A4: Add critical event lists (FW, Ring, App) and guide | B4: 46282 | C4: First cut for the issue tracker; see Critical Events Guide

Sheet FW Logs-不发布，内部使用
A1: 序号 | B1: Type | C1: Log function | D1: Description
A2: 1 | B2: 系统 | C2: ER: MallocFailed! %d | D2: FreeRTOS内存分配失败，打印剩余堆大小
A3: 2 | B3: 系统 | C3: ER: StackOverflow! | D3: FreeRTOS任务栈溢出错误
A4: 3 | B4: 存储 | C4: user_read %d 0x%x | D4: 用户数据读取信息，显示长度和最后一个字节
A5: 4 | B5: 存储 | C5: apollo_flash_init 1 | D5: Apollo Flash初始化成功
A6: 5 | B6: 存储 | C6: apollo_flash_init 0 | D6: Apollo Flash初始化失败
A7: 6 | B7: 系统 | C7: Reset Status Register = 0x%x | D7: 复位状态寄存器的值
A8: 7 | B8: 系统 | C8: power on | D8: 设备上电启动
A9: 8 | B9: 系统 | C9: FW %d.%d.%d size:%d | D9: 固件版本号和Ring缓冲区大小
A10: 9 | B10: 系统 | C10: SN:%s | D10: 设备序列号
A11: 10 | B11: 系统 | C11: App ful:%d,%d,%d %d | D11: 应用任务队列满时的调试信息（当前消息、时间戳、类型、失败计数）
A12: 11 | B12: 充电电池 | C12: rbc=%d,bc=%d,%d,cst=%d | D12: 电池状态变化时的打印（报告电量、保存电量、当前电量、充电状态）
A13: 12 | B13: 充电电池 | C13: battery_low_remind_send | D13: 电池低电量提醒发送
... A289: 288 | B289: 日志 | C289: ble:%d bht:%d blt:%d ht:%d spo2t:%d spt:%d tpt:%d led:%d motor:%d val:%d steps:%d,BindTime:%d | D289: 记录戒指行为统计（蓝牙在线/高低速时长、心率/血氧/运动时长、LED/马达时长、电量、步数、绑定时间等）

Sheet Ring Logs-iOS
B2: Slno | C2: Type | D2: FunctionId | E2: Log function | F2: Description
B3: 1 | C3: 连接 | E3: _restoredPeriopheral | F3: 通过恢复设备--设置连接设备
B4: 2 | C4: 连接 | E4: 蓝牙断开 error: | F4: 蓝牙断开
B5: 3 | C5: 连接 | E5: 蓝牙连接失败 | F5: 蓝牙连接失败
B6: 4 | C6: 信息通讯 | D6: 0 | E6: MtuRequestChange | F6: change_mtu
B7: 5 | C7: 信息通讯 | D7: 16 | E7: InquiryBindingStatus | F7: Bind_Account-InquiryBindingStatus
B8: 6 | C8: 信息通讯 | D8: 17 | E8: BindingCheck | F8: Bind_Account-绑定连接：绑定校验(app->设备)
B9: 7 | C9: 信息通讯 | D9: 18 | E9: BindingResult | F9: Bind_Account-绑定连接：绑定回复(app->设备)
B10: 8 | C10: 信息通讯 | D10: 19 | E10: VerifyUserNumber | F10: 账号校验
B11: 9 | C11: 信息通讯 | D11: 20 | E11: InquiryPairingStatus | F11: 获取当前的配对状态
B12: 10 | C12: 信息通讯 | D12: 21 | E12: RequestPairing | F12: 发起配对
B13: 11 | C13: 信息通讯 | D13: 22 | E13: RequestPairingResult | F13: 配对回调结果下发
B14: 12 | C14: 信息通讯 | D14: 23 | E14: UnbindRequest | F14: 解绑请求
B15: 13 | C15: 信息通讯 | D15: 24 | E15: DeviceRestart | F15: 重启请求(app->设备)
B16: 14 | C16: 信息通讯 | D16: 25 | E16: InquiryClassicBluetoothConnectStatus | F16: 获取经典蓝牙的连接状态
B17: 15 | C17: 信息通讯 | D17: 26 | E17: DeviceShutdown | F17: 关机指令请求(app->设备)
... B330: 328 | C330: 信息通讯 | D330: 4112 | E330: WearSendDeveloperData | F330: 设备上报开发者采集数据

Sheet Ring Logs-Android
A2: Slno | B2: Type | C2: Log function | D2: Description
A3: 1 | B3: 连接 | C3: connect() name:Luna Ring_0296,address:D8:37:04:60:02:96 | D3: App 发起连接，address：mac地址
A4: 2 | B4: 连接 | C4: init initDeviceCmd and init device channel over | D4: 设备连接成功
A5: 3 | B5: 连接 | C5: newState =0 | D5: 设备断连
A6: 4 | B6: 信息通讯 | C6: controlbletools ----------> | D6: App发送指令
A7: 5 | B7: 信息通讯 | C7: parsing id = 00 73 = 115 --> CONFIRM_FITNESS_TYPE_ID errorCode = 0 | D7: “errorCode = 0”指令通讯成功
A8: 6 | B8: 信息通讯 | C8: getDailyHistoryData() | D8: App 获取日常数据
A9: 7 | B9: 信息通讯 | C9: parsingFitness continuousHeartRateData = | D9: 设备回复连续心率数据
A10: 8 | B10: 信息通讯 | C10: parsingFitness continuousBloodOxygenData = | D10: 设备回复连续血氧数据
A11: 9 | B11: 信息通讯 | C11: parsingFitness continuousPressureData = | D11: 设备回复连续压力数据
A12: 10 | B12: 信息通讯 | C12: parsingFitness continuousTemperatureData = | D12: 设备回复连续温度数据
A13: 11 | B13: 信息通讯 | C13: parsingFitness overallDayMovementData = | D13: 设备回复GoMore算法全天活动指标数据
A14: 12 | B14: 信息通讯 | C14: parsingFitness todayActiveTypeData = | D14: 设备回复GoMore算法活动类型指标数据
... A290: 288 | B290: 信息通讯 | C290: GET_QR_CODE_SETTINGS | D290: 获取二维码设置
B291: 信息通讯 | C291: SET_QR_CODE_SETTINGS | D291: 设置二维码设置
B292: 信息通讯 | C292: REQUEST_GET_QR_CODE_SETTINGS | D292: 请求获取二维码设置
B293: 信息通讯 | C293: GET_ESIM_EID_SETTINGS | D293: 请求获取手表端esim的EID设置
B294: 信息通讯 | C294: SET_ESIM_BIGDATA_SETTINGS | D294: 设置手表端esim超大数据设置
B295: 信息通讯 | C295: GET_ESIM_COMMON_DATA_SETTINGS | D295: 获取esim的普通设置
B296: 信息通讯 | C296: SET_ESIM_COMMON_DATA_SETTINGS | D296: 设置esim的普通设置
B297: 信息通讯 | C297: DELETE_ESIM_SETTINGS | D297: 删除esim的卡的ID
B298: 信息通讯 | C298: SEND_ESIM_HTTP_DATA | D298: 发送esimhttp数据给到APP
B299: 信息通讯 | C299: SET_RING_AIRPLANEMODE | D299: 戒指开启飞行模式
B300: 信息通讯 | C300: GET_SPO2_MONITOR | D300: 获取血氧监测参数
B301: 信息通讯 | C301: SET_SPO2_MONITOR | D301: 设置血氧监测参数
B302: 信息通讯 | C302: REQUEST_SPO2_MONITOR | D302: 请求获取血氧监测参数
... B342: 信息通讯 | C342: SYNC_INSTRUCTION | D342: 同步aleax指令

Sheet App Logs
B2: Slno | C2: Type | D2: Log function | E2: Description

Sheet Critical Events Guide
A1: Critical events to track: first cut
A2: Prepared 2026-09-17 for the Wearable Issue Tracker (PRD draft v3, event model D24). The three sheets after this one list the events the apps should send. The vendor's original sheets are unchanged.
A4: How to read the event sheets
A5: Priority | B5: P0 = must track in v1: data loss, a core flow failing (connect, pair, sync, OTA, upload, login) or a device fault. P1 = track in v1 if cheap, otherwise soon after. P2 = later.
A6: Kind: Exception (red row) | B6: The firmware, SDK or app prints an explicit error at this point today.
A7: Kind: Derived | B7: No error line exists; a rule over normal lines or app state detects it (e.g. restart cause from the reset register).
A8: Kind: Context | B8: Not a fault, but explains faults (Bluetooth off, battery died, planned reboot).
A9: Kind: Not logged | B9: Nothing is logged today; the app needs a new call site.
A10: Type | B10: D24 / PRD §7.1: failure (a tracked operation failed; counted against attempts) · exception (an error outside a tracked operation) · anomaly (abnormal device or data behaviour, no error raised) · gap (expected data missing) · context (explains faults, never alerts).
A11: Severity | B11: critical = data loss or product unusable · error = a user-visible operation failed · warning = degraded or recovered · info = context.
A12: Name · reason · tag | B12: Names are device-neutral area.what (device.restart, not ring.restart). Reasons are short and bounded, never ids. Tags come from luna-feedback-app's diagnosis list so feedback and issues can be joined.
A13: One fault, one event | B13: When the app and a log both see the same fault (e.g. a disconnect), the app emits the event and the log supplies the reason. Firmware rows are detected by the app while it parses the firmware log.
A14: Evidence columns | B14: Counts from real logs in ~/Downloads (internal testers and support tickets, not a random fleet sample). They show what happens in the field, not fleet rates. "Not seen" means the line exists in code but did not appear in the samples.
A16: Samples behind the evidence
A17: Sample | B17: What it is | C17: Files | D17: Distinct rings | E17: Period
A18: Firmware logs, 2026 | B18: firmware_logs.txt uploads + luna-fw-*.log Diagnostics shares, de-duplicated | C18: 52 | D18: 39 | E18: Mar–Sep 2026
A19: Firmware logs, 2025 | B19: Same sources, older firmware (1.1.x) | C19: 79 | D19: 58 | E19: Sep–Dec 2025
A20: iOS ring traces, 2026 | B20: ring-trace-*.log and watchLogs uploads (ZHD SDK 2.2.3–2.4.7) | C20: 36 | D20: — | E20: Jan–Sep 2026
A21: iOS app logs, 2026 | B21: luna-app-*.log and appLogs uploads in the current format | C21: 43 | D21: — | E21: Aug–Sep 2026
A22: Android ring logs, 2026 | B22: BEHAVIOR_<date>.log from Ring_log zips (days) | C22: 13 | D22: — | E22: May and Sep 2026
A23: Android app logs | B23: appLogs.txt with X-LOG lines | C23: 17 | D23: — | E23: 16 from 2025, 1 from 2026
A24: Blue numbers are counted from the sample files; the "% of 2026 rings" column in the firmware sheet divides by the 2026 ring count above.
A26: Events per sheet
A27: Sheet | B27: Covers | C27: P0 | D27: P1 | E27: P2 | F27: Exception rows
A28: FW Critical Events | B28: Firmware log lines, detected by the app while it parses the firmware log | C28: =COUNTIF('FW Critical Events'!$B$4:$B$200,"P0") | D28: =COUNTIF('FW Critical Events'!$B$4:$B$200,"P1") | E28: =COUNTIF('FW Critical Events'!$B$4:$B$200,"P2") | F28: =COUNTIF('FW Critical Events'!$D$4:$D$200,"Exception")
A29: Ring Critical Events | B29: ZHD (iOS) and ZH (Android) SDK logs and SDK error codes | C29: =COUNTIF('Ring Critical Events'!$B$4:$B$200,"P0") | D29: =COUNTIF('Ring Critical Events'!$B$4:$B$200,"P1") | E29: =COUNTIF('Ring Critical Events'!$B$4:$B$200,"P2") | F29: =COUNTIF('Ring Critical Events'!$D$4:$D$200,"Exception")
A30: App Critical Events | B30: App log call sites on iOS and Android, emitted directly by the app | C30: =COUNTIF('App Critical Events'!$B$4:$B$200,"P0") | D30: =COUNTIF('App Critical Events'!$B$4:$B$200,"P1") | E30: =COUNTIF('App Critical Events'!$B$4:$B$200,"P2") | F30: =COUNTIF('App Critical Events'!$D$4:$D$200,"Exception")
A31: Total | C31: =SUM(C28:C30) | D31: =SUM(D28:D30) | E31: =SUM(E28:E30) | F31: =SUM(F28:F30)
A33: What the logs showed
A34: • | B34: The FW Logs sheet is most of the firmware command-code dictionary that PRD §7.4 is blocked on. Checked against 131 real firmware logs, the restart cause reads straight from the Reset Status Register: every 0x40 followed `WDT isr save` (21 of 21, at 95% battery), 0x86 followed `HUB_MSG_POWER_OFF` at 1–2% battery, and 0x8 followed a planned-restart marker (OTA, factory reset, app request). Most blocked device rows can move to detectable.
A35: • | B35: Real firmware logs contain important lines the vendor sheet doesn't list: `DM_CONN_CLOSE_IND, reason = 0x..`, `DM_SEC_PAIR_FAIL_IND, status = 0x..`, `HUB_MSG_POWER_OFF`, the restart save markers (`hub_restart_save`, `fac_reboot_save`, `default_reset_save`, `ota_ok_save`, `lpm_save`), `wlc init failed`, `Err: nfc sleep abnormal`, `Fifo error reinit GS`, `verify UID:.. VID:..`, `charge_status`, `noti not open`, `ER CNF`, `SPO2_not_data`, `hourly_save`. The sheet also writes `I2C_device_Init` where the firmware prints `i2c_device_Init`.
A36: • | B36: 41% of 2026 ring-side syncs (190 of 458) requested data and never sent the confirm command (cmd 123), against 3% in 2025. The iOS app logs `receipt ack SKIPPED (partial-scope)` in 23 of 43 app logs. This is where re-sent, duplicate data comes from.
A37: • | B37: Android's `E/X-LOG: Exception = 01 FF` is not an exception. It is the Connect / Other lifecycle marker (Connect, Connected, Initialized, Release). Only `01 02` (connect failed) and `02 02` (bind failed) are failures, and the SyncData / OTA codes are never emitted. PRD §7.3 should change.
A38: • | B38: Android `Timber.w/e` lines go to logcat only (LOGS is a DebugTree), so forced logout, the foreground-service timeout, Health Connect failures and `upload_logs failed` never reach the uploaded log. Those need events.
A39: • | B39: 10 of the 52 firmware logs from 2026 (all 1–20 Aug) were 56–97% binary and unusable, so the log pipeline itself needs a data-quality event.
A40: • | B40: Rings reboot for real: watchdog resets on 2 of 39 rings in 2026 (after `hub ful`), an ADC-fault restart loop in 2025 (316 on one ring), and power loss with battery left on 12 of 58 rings in 2025.
A41: • | B41: On iOS, future-dated samples are dropped in 41 of 43 app logs, and the push-token upload fails in 18 of 43 (the response can't be decoded). Both are worth a quick look before they are tracked.
A43: Asks for the firmware vendor
A44: 1. | B44: Confirm the Reset Status Register bits (samples fit the Ambiq Apollo layout: 0x02 power-on, 0x04 brown-out, 0x08 software, 0x40 watchdog, 0x80 unregulated brown-out).
A45: 2. | B45: Add the lines listed above to the dictionary.
...

Sheet FW Critical Events
A1: Firmware log: critical events to track
A2: Detected by the app while it parses the firmware log (source = firmware_log, domain = firmware). Red rows are lines where the firmware prints an explicit error. Rows are grouped by area, P0 first within each area.
A3: # | B3: Priority | C3: Area | D3: Kind | E3: Event name | F3: Reason(s) | G3: Type | H3: Severity | I3: Log line(s) to match | J3: FW Logs 序号 | K3: Detection rule (in the app) | L3: What it means / why track it | M3: 2026 lines | N3: 2026 rings (of 39) | O3: % of 2026 rings | P3: 2025 rings (of 58) | Q3: Tag | R3: Open question for the vendor
A4: FW-01 | B4: P0 | C4: System & restarts | D4: Exception | E4: device.restart | F4: watchdog | G4: anomaly | H4: critical | I4: WDT isr save Reset Status Register = 0x%x (value 0x40) power on — detail lines — WDT App:%d,T:%d,%d %d,P:%d,W:%d WDT hub:%d,P:%d %d,T:%d,%d %d, W:%d WDT hub:W:%d,H:%d WDT: cur time:%d, H:%d, mible_mux:%d, link buf mux:%d | J4: 87, 6, 7, 19, 21, 22, 23 | K4: `power on` whose preceding `Reset Status Register` has bit 0x40 set, or `WDT isr save` within the 60 lines before it. Put the WDT task, stack watermark (W) and free heap (H) in properties. | L4: A firmware task hung and the watchdog rebooted the ring. Measurements in progress are lost and repeated resets drain the battery. In every sample it came seconds after `hub ful` (hub queue full), at 95% battery. | M4: 21 | N4: 2 | O4: =IF(ISNUMBER(N4),N4/'Critical Events Guide'!$D$18,"—") | P4: 1 | Q4: firmware_reboot | R4: Confirm the Reset Status Register bits. Samples fit the Ambiq Apollo layout: 0x40 watchdog, 0x08 software, 0x04 brown-out, 0x02 power-on, 0x80 unregulated brown-out.
A5: FW-02 | B5: P0 | C5: System & restarts | D5: Derived | E5: device.restart | F5: power_loss | G5: anomaly | H5: critical | I5: Reset Status Register = 0x%x (value 0x86) power on | J5: 6, 7 | K5: `power on` with register 0x86 (power-on + brown-out), no `HUB_MSG_POWER_OFF`, `enter shipping mode` or `no_bind off` in the 60 lines before, and the last battery reading (rbc= / val:) above 5%. | L5: The ring lost power while the battery was not empty: battery contact, PMIC or board fault. The clock restarts at its default date, so the next hours of data are mis-dated. | M5: 6 | N5: 2 | O5: =IF(ISNUMBER(N5),N5/'Critical Events Guide'!$D$18,"—") | P5: 12 | Q5: firmware_reboot | R5: Is `HUB_MSG_POWER_OFF` written before every controlled power-off (low battery, shipping, unbind, user)?
A6: FW-03 | B6: P0 | C6: System & restarts | D6: Derived | E6: device.restart | F6: brownout | G6: anomaly | H6: critical | I6: Reset Status Register = 0x%x (value 0x84) power on | J6: 6, 7 | K6: `power on` with brown-out bit 0x04 set and power-on bit 0x02 clear. | L6: Supply voltage dipped (a motor or radio peak on a weak battery) and reset the MCU without a full power loss. | M6: 0 | N6: 0 | O6: =IF(ISNUMBER(N6),N6/'Critical Events Guide'!$D$18,"—") | P6: 3 | Q6: firmware_reboot
A7: FW-04 | B7: P0 | C7: System & restarts | D7: Derived | E7: device.restart | F7: unexpected | G7: anomaly | H7: critical | I7: Reset Status Register = 0x%x (value 0x8) power on — with no planned-restart marker before it | J7: 6, 7 | K7: `power on` with register 0x08 (software reset) and none of `hub_restart_save`, `fac_reboot_save`, `default_reset_save`, `apprequest_reset`, `ota_ok_save`, `lpm_save`, `sys idle reboot` or `cmd: 24` in the 60 lines before. | L7: A software reset nobody asked for, typically an assert or fault handler. This is what separates a crash from a planned reboot. | M7: 1 | N7: 1 | O7: =IF(ISNUMBER(N7),N7/'Critical Events Guide'!$D$18,"—") | P7: 4 | Q7: firmware_reboot | R7: Do assert / hard-fault handlers log anything before resetting? A unique line (e.g. `ER: HardFault pc=0x..`) would make this exact.
A8: FW-05 | B8: P0 | C8: System & restarts | D8: Exception | E8: device.restart | F8: adc_fault | G8: anomaly | H8: critical | I8: unchg: reinit adc chg: reinit adc → hub_restart_save → power on | J8: 175, 174 | K8: `unchg: reinit adc` or `chg: reinit adc`, followed by `hub_restart_save` and a reboot. | L8: Battery ADC reading was abnormal, so the firmware restarted the system. In the 2025 samples one ring did this 316 times, a reboot loop around 20% battery. | M8: 12 | N8: 4 | O8: =IF(ISNUMBER(N8),N8/'Critical Events Guide'!$D$18,"—") | P8: 1 | Q8: battery | R8: What makes the ADC reading abnormal, and is the 2025 reboot loop fixed in 1.2.x?
A9: FW-06 | B9: P0 | C9: System & restarts | D9: Exception | E9: firmware.fault | F9: out_of_memory | G9: anomaly | H9: critical | I9: ER: MallocFailed! %d ER malloc:L%d ER Mem: 0 ER:send malloc %d ER s_init no mem ER: malloc send obj00, used size: %d ER: malloc send obj20, used size: %d ER: malloc send obj21, used size: %d ER rcv mem: %d malloc_res error ER malloc 8KB failed ER sleep malloc:%d | J9: 1, 13, 18, 46, 47, 48, 52, 93, 95, 97, 99, 100, 101, 102, 117, 120, 121, 131, 133, 246, 253, 265 | K9: Any of these lines. Call-site line number (L%d) or requested size goes in properties. Field logs print `ER: malloc send obj2` (no size), so match the prefix. | L9: Heap exhausted: the operation is dropped (BLE send, sleep save, GoMore, storage). A precursor to watchdog resets and lost data. | M9: 36 | N9: 2 | O9: =IF(ISNUMBER(N9),N9/'Critical Events Guide'!$D$18,"—") | P9: 0 | Q9: firmware_cmd_error | R9: `ER malloc:L%d` is printed from 11 places with the same text. Add a module prefix, or share the line-to-module map per firmware version.
A10: FW-07 | B10: P0 | C10: System & restarts | D10: Exception | E10: firmware.fault | F10: stack_overflow | G10: anomaly | H10: critical | I10: ER: StackOverflow! | J10: 2 | K10: Line present. Add the task name to properties once the firmware logs it. | L10: A FreeRTOS task overflowed its stack. Memory corruption and a reset usually follow. | M10: 0 | N10: 0 | O10: =IF(ISNUMBER(N10),N10/'Critical Events Guide'!$D$18,"—") | P10: 0 | Q10: firmware_cmd_error | R10: Can the overflowing task name be logged on this line?
A11: FW-08 | B11: P0 | C11: System & restarts | D11: Exception | E11: firmware.fault | F11: malloc_in_isr | G11: anomaly | H11: critical | I11: ER Malloc in interrup! | J11: 247 | K11: Line present. | L11: Memory allocation attempted inside an interrupt: a firmware bug that can corrupt the heap. | M11: 0 | N11: 0 | O11: =IF(ISNUMBER(N11),N11/'Critical Events Guide'!$D$18,"—") | P11: 0 | Q11: firmware_cmd_error
A12: FW-09 | B12: P0 | C12: System & restarts | D12: Exception | E12: firmware.fault | F12: queue_full | G12: anomaly | H12: error | I12: hub ful:%d,P:%d %d,T:%d,%d %d %d,W:%d,H:%d App ful:%d,%d,%d %d hub_queue_handlefull %d %d hub_queue_handlefullint %d %d | J12: 20, 10, 26, 27 | K12: Any of these lines. Fold repeats within 5 minutes into one event with a count. | L12: A firmware task queue is full, so messages are dropped. In the samples it preceded every watchdog reset by seconds. | M12: 89 | N12: 2 | O12: =IF(ISNUMBER(N12),N12/'Critical Events Guide'!$D$18,"—") | P12: 0 | Q12: firmware_cmd_error
A13: FW-10 | B13: P1 | C13: System & restarts | D13: Derived | E13: device.restart_loop | G13: anomaly | H13: critical | I13: power on (3 or more) | J13: 7 | K13: 3 or more `power on` of any reason within 60 minutes of device time. | L13: A reboot loop drains the battery and loses all data, while each single restart can look minor. Devices-affected alerting cannot see a loop on one ring, so it needs its own name. | M13: 5 | N13: 3 | O13: =IF(ISNUMBER(N13),N13/'Critical Events Guide'!$D$18,"—") | P13: 9 | Q13: firmware_reboot
A14: FW-11 | B14: P1 | C14: System & restarts | D14: Context | E14: device.restart_planned | F14: ota · factory_reset · app_request · low_power · idle · firmware_request | G14: context | H14: info | I14: ota_ok_save fac_reboot_save default_reset_save · apprequest_reset lpm_save sys idle reboot hub_restart_save cmd: %d,%d (24 = DeviceRestart) → Reset Status Register = 0x8 → power on | J14: 147, 135, 6, 7 (save markers not in sheet) | K14: `power on` with register 0x08 preceded by a save marker. Reason from the marker; `hub_restart_save` is `firmware_request` unless an ADC fault came first (then it is `device.restart` / `adc_fault`). | L14: Expected reboots. Needed so the restart faults above exclude them, and so a burst of planned reboots is still visible. | M14: 54 | N14: 8 | O14: =IF(ISNUMBER(N14),N14/'Critical Events Guide'!$D$18,"—") | P14: 15 | Q14: firmware_reboot | R14: Add the save markers to the dictionary. What else triggers `hub_restart_save`? Is `sys idle reboot` a scheduled maintenance reboot?
A15: FW-12 | B15: P1 | C15: System & restarts | D15: Context | E15: device.power_off | F15: battery_depleted · shipping_mode · unbound · user_request · fault | G15: context | H15: info | I15: HUB_MSG_POWER_OFF enter shipping mode no_bind off cmd: %d,%d (26 = DeviceShutdown) Err: nfc sleep abnormal, power off | J15: 89, 135 (HUB_MSG_POWER_OFF, shipping mode not in sheet) | K15: Power-off marker. Reason from the line before it; `battery_depleted` when the last battery reading was 5% or less. The next boot (0x86) is then not a fault. | L15: Explains data gaps and cold boots. A battery that died overnight is the commonest innocent cause of "no sleep data". | M15: 50 | N15: 3 | O15: =IF(ISNUMBER(N15),N15/'Critical Events Guide'!$D$18,"—") | P15: 9 | Q15: battery | R15: Add `HUB_MSG_POWER_OFF` and `enter shipping mode` to the dictionary.
A16: FW-13 | B16: P1 | C16: System & restarts | D16: Exception | E16: firmware.fault | F16: mutex_timeout | G16: anomaly | H16: error | I16: ER: mux timeout:%d ER mux timeout:%d ER: mux give | J16: 90, 91, 92 | K16: Any of these lines. | L16: The SAR mutex was not acquired within 20 s, or could not be released. A deadlock precursor. | M16: 0 | N16: 0 | O16: =IF(ISNUMBER(N16),N16/'Critical Events Guide'!$D$18,"—") | P16: 0 | Q16: firmware_cmd_error
A17: FW-14 | B17: P2 | C17: System & restarts | D17: Derived | E17: device.memory_low | G17: anomaly | H17: warning | I17: gdiff:%d,st:%d-%d,0x%02x,hp=%d,adc=%d,InSleep=%d (hourly) infowear: %d,free hp size = %d WDT: cur time:%d, H:%d, mible_mux:%d, link buf mux:%d | J17: 31, 98, 21 | K17: Free heap (hp= / H: / free hp size) below an agreed floor, or falling day over day on the same firmware. | L17: Catches a slow leak before malloc failures and watchdog resets. Hourly free heap in the samples ranges from about 138 KB to 180 KB. | M17: — | N17: — | O17: =IF(ISNUMBER(N17),N17/'Critical Events Guide'!$D$18,"—") | P17: — | Q17: firmware_cmd_error | R17: Input lines on 24 of 39 rings (2026); threshold still to set. What free-heap level is dangerous?
A18: FW-15 | B18: P0 | C18: Power & charging | D18: Exception | E18: battery.fault | F18: pmic_init_failed | G18: anomaly | H18: critical | I18: cw6305b init fail ! | J18: 204 | K18: Line present (boot sequence). | L18: The charging / power-management IC failed to initialise at boot. The ring may not charge or report battery. | M18: 0 | N18: 0 | O18: =IF(ISNUMBER(N18),N18/'Critical Events Guide'!$D$18,"—") | P18: 1 | Q18: battery
A19: FW-16 | B19: P0 | C19: Power & charging | D19: Exception | E19: battery.fault | F19: wireless_charger_init_failed | G19: anomaly | H19: critical | I19: wlc init failed | J19: Not in sheet | K19: Line present (boot sequence, after `cw6305b init ok !`). | L19: The wireless-charging receiver failed to initialise at boot. Seen on every boot of one 2026 ring. | M19: 36 | N19: 1 | O19: =IF(ISNUMBER(N19),N19/'Critical Events Guide'!$D$18,"—") | P19: 0 | Q19: battery | R19: Add `wlc init failed` / `wlc init succeeded` to the dictionary and confirm the impact.
A20: FW-17 | B20: P0 | C20: Power & charging | D20: Exception | E20: battery.fault | F20: nfc_sleep_abnormal | G20: anomaly | H20: critical | I20: Err: nfc sleep abnormal Err: nfc sleep abnormal, power off | J20: Not in sheet | K20: Either line. The second is followed by `HUB_MSG_POWER_OFF` and a reboot. | L20: The NFC / wireless-charging receiver sleep state is abnormal. The second form powers the ring off. | M20: 28 | N20: 1 | O20: =IF(ISNUMBER(N20),N20/'Critical Events Guide'!$D$18,"—") | P20: 0 | Q20: battery | R20: What is "nfc sleep", and how does it relate to cmd 419 (RequestNfcSleepErr)?
A21: FW-18 | B21: P0 | C21: Power & charging | D21: Exception | E21: battery.fault | F21: adc_read_failed | G21: anomaly | H21: error | I21: read_ADC_fail:%d | J21: 162 | K21: Line present. | L21: Battery voltage could not be read, so the battery % shown in the app becomes unreliable. | M21: 0 | N21: 0 | O21: =IF(ISNUMBER(N21),N21/'Critical Events Guide'!$D$18,"—") | P21: 5 | Q21: battery
A22: FW-19 | B22: P0 | C22: Power & charging | D22: Exception | E22: battery.fault | F22: voltage_abnormal | G22: anomaly | H22: error | I22: Battery voltage abnormal: %dmV | J22: 155 | K22: Line present. Voltage in properties. | L22: Battery voltage outside the normal range: a possible cell or charging fault. New battery-management logs, not in any sample yet. | M22: 0 | N22: 0 | O22: =IF(ISNUMBER(N22),N22/'Critical Events Guide'!$D$18,"—") | P22: 0 | Q22: battery | R22: What range counts as abnormal?
A23: FW-20 | B23: P0 | C23: Power & charging | D23: Derived | E23: battery.sudden_drop | G23: anomaly | H23: error | I23: rbc=%d,bc=%d,%d,cst=%d M:rbc=%d,bc=%d,%d,cst=%d ble:%d bht:%d … val:%d steps:%d,BindTime:%d (every 20 min) adc %d,val %d-%d,st %d | J23: 11, 132, 288, 164 | K23: Battery level falls 15 points or more within 2 hours with no charging in between (charge_status / st / cst). | L23: Abnormal drain or a bad fuel-gauge reading. Already in PRD §7.4 as unblocked. | M23: 0 | N23: 0 | O23: =IF(ISNUMBER(N23),N23/'Critical Events Guide'!$D$18,"—") | P23: 2 | Q23: battery | R23: Confirm the fields: rbc (reported), bc (saved), current, cst (charge state: 0/1/2 meaning?).
A24: FW-21 | B24: P1 | C24: Power & charging | D24: Exception | E24: battery.fault | F24: bms_data_invalid | G24: anomaly | H24: warning | I24: Battery management system data not found or invalid, initializing to default values | J24: 159 | K24: Line present. | L24: Battery-management state was lost and reset to defaults. Battery % and health estimates may jump. | M24: 0 | N24: 0 | O24: =IF(ISNUMBER(N24),N24/'Critical Events Guide'!$D$18,"—") | P24: 0 | Q24: battery
A25: FW-22 | B25: P1 | C25: Power & charging | D25: Exception | E25: battery.fault | F25: percent_inconsistent | G25: anomaly | H25: warning | I25: Battery percent inconsistent: %d vs %d | J25: 156 | K25: Line present. Both values in properties. | L25: Calculated and reported battery % disagree. Users see jumps or a wrong level. | M25: 0 | N25: 0 | O25: =IF(ISNUMBER(N25),N25/'Critical Events Guide'!$D$18,"—") | P25: 0 | Q25: battery
A26: FW-23 | B26: P1 | C26: Power & charging | D26: Exception | E26: battery.health_poor | G26: anomaly | H26: warning | I26: Battery health poor: %.1f%% | J26: 157 | K26: Line present. Health % in properties. | L26: Battery health is below 50%. Expect short battery-life complaints; a replacement candidate. | M26: 0 | N26: 0 | O26: =IF(ISNUMBER(N26),N26/'Critical Events Guide'!$D$18,"—") | P26: 0 | Q26: battery
A27: FW-24 | B27: P1 | C27: Power & charging | D27: Derived | E27: battery.drain_high | G27: anomaly | H27: warning | I27: Battery usage mode changed from %d to %d (avg current: %f mA) ble:%d bht:%d blt:%d ht:%d spo2t:%d spt:%d tpt:%d led:%d motor:%d val:%d steps:%d,BindTime:%d | J27: 158, 288 | K27: Average current above an agreed limit, or battery % per hour above the fleet baseline. Attach the on-time counters (BLE high-speed, HR, SpO2, temperature, LED, motor) as properties. | L27: Answers "battery drains fast" tickets with the component that drew the power. | M27: — | N27: — | O27: =IF(ISNUMBER(N27),N27/'Critical Events Guide'!$D$18,"—") | P27: — | Q27: battery | R27: Input lines on 3 of 39 rings (2026); threshold still to set. Units of ble / bht / blt / ht / spo2t / spt / tpt / led / motor (seconds since bind?). What average current is abnormal?
A28: FW-25 | B28: P1 | C28: Power & charging | D28: Derived | E28: battery.charge_fault | F28: flapping · forced_full | G28: anomaly | H28: warning | I28: charge_status:now:%d,old:%d (95)adc %d,val %d-%d,st %d fulflag %d-%d 0:99-100 1:99-100 2:99-100 fcadc %d | J28: 165, 166, 167, 169, 173 (charge_status not in sheet) | K28: flapping: 6 or more charge-state changes within 10 minutes. forced_full: path `0:99-100` (stuck at 99% for 15 minutes, then forced to 100%). | L28: Poor charger contact or a charging-IC problem. Behind "stuck at 99%" and "stops charging" tickets. | M28: — | N28: — | O28: =IF(ISNUMBER(N28),N28/'Critical Events Guide'!$D$18,"—") | P28: — | Q28: battery | R28: Input lines on 4 of 39 rings (2026); threshold still to set.
A29: FW-26 | B29: P2 | C29: Power & charging | D29: Context | E29: battery.low | G29: context | H29: info | I29: battery_low_remind_send lowpower_vibration_motor... | J29: 12, 172 | K29: Either line. | L29: A low-battery warning was given (20% / 10%). Explains the power-off that usually follows. | M29: 0 | N29: 0 | O29: =IF(ISNUMBER(N29),N29/'Critical Events Guide'!$D$18,"—") | P29: 0 | Q29: battery
A30: FW-27 | B30: P0 | C30: Storage & time | D30: Exception | E30: storage.fault | F30: flash_init_failed | G30: anomaly | H30: critical | I30: apollo_flash_init 0 flash init_err | J30: 5, 249 | K30: Either line (boot sequence). | L30: Internal or external flash failed to initialise at boot, so nothing can be stored. | M30: 0 | N30: 0 | O30: =IF(ISNUMBER(N30),N30/'Critical Events Guide'!$D$18,"—") | P30: 2 | Q30: data_gap | R30: Does the ring keep running after `apollo_flash_init 0`, and what is lost?
A31: FW-28 | B31: P0 | C31: Storage & time | D31: Exception | E31: storage.fault | F31: read_write_failed | G31: anomaly | H31: critical | I31: ER read at offset %d ER write at offset %d ER write new data ER data shift failed | J31: 254, 255, 256, 257 | K31: Any of these lines. | L31: Daily data could not be read, moved or written. That day's data is lost. | M31: 0 | N31: 0 | O31: =IF(ISNUMBER(N31),N31/'Critical Events Guide'!$D$18,"—") | P31: 0 | Q31: data_gap
A32: FW-29 | B32: P0 | C32: Storage & time | D32: Exception | E32: storage.fault | F32: header_corrupt | G32: anomaly | H32: critical | I32: func:%s,line:%d,type:%d | J32: 250, 251, 252 | K32: Line matches `func:<name>,line:<n>,type:<n>`. | L32: The daily-data header address check failed on read, delete or save, so the header was re-initialised. Stored days can disappear ("lost sleep data"). | M32: 0 | N32: 0 | O32: =IF(ISNUMBER(N32),N32/'Critical Events Guide'!$D$18,"—") | P32: 0 | Q32: data_gap | R32: Give this line a unique prefix (e.g. `ER hdr:`). `func:%s` is too generic to match safely.
A33: FW-30 | B33: P1 | C33: Storage & time | D33: Exception | E33: storage.user_info_reset | G33: anomaly | H33: warning | I33: %s (logged after user info is restored to defaults) | J33: 261 | K33: Not detectable until the line has fixed text. | L33: User settings on the ring went back to defaults: alarms, reminders and profile are lost. | M33: — | N33: — | O33: =IF(ISNUMBER(N33),N33/'Critical Events Guide'!$D$18,"—") | P33: — | Q33: data_gap | R33: Needs a fixed string, e.g. `user info reset: %s`.
A34: FW-31 | B34: P1 | C34: Storage & time | D34: Derived | E34: storage.data_reset | G34: anomaly | H34: warning | I34: data reset %d! | J34: 24 | K34: `data reset <epoch>!`. In the samples it follows `cmd: 48` (set time) when the ring clock was still at its default date. | L34: The daily-data store was reset, apparently when the time was corrected. Data recorded under the wrong date may be dropped. | M34: 3 | N34: 3 | O34: =IF(ISNUMBER(N34),N34/'Critical Events Guide'!$D$18,"—") | P34: 6 | Q34: data_gap | R34: Confirm what `data reset` clears and when it runs.
A35: FW-32 | B35: P1 | C35: Storage & time | D35: Derived | E35: device.clock_reset | G35: anomaly | H35: warning | I35: read: %d-%d-%d modify: %d-%d-%d — or lines stamped at the default date (3-1 06:xx) after a cold boot | J35: 262, 263 | K35: `read:` / `modify:` pair, or firmware lines dated at the default date after a cold boot, until `cmd: 48` (SetSystemTime) arrives. | L35: The ring clock restarted at a default date. Anything measured before the app sets the time is mis-dated or dropped. | M35: 363 | N35: 3 | O35: =IF(ISNUMBER(N35),N35/'Critical Events Guide'!$D$18,"—") | P35: 7 | Q35: time_zone | R35: What is the default date after power loss on 1.2.x (samples show 3-1 06:06)?
A36: FW-33 | B36: P1 | C36: Storage & time | D36: Exception | E36: device.time_jump | G36: anomaly | H36: warning | I36: HUB_MSG_GM_RESET %d %d gm reset: Time difference exceeded | J36: 113, 50 | K36: Either line. Old and new timestamps in properties. | L36: Device time changed by more than 20 minutes, so GoMore restarted and its running metrics (stress, body battery, training load) reset. | M36: 22 | N36: 4 | O36: =IF(ISNUMBER(N36),N36/'Critical Events Guide'!$D$18,"—") | P36: 12 | Q36: time_zone
A37: FW-34 | B37: P0 | C37: Sensors | D37: Exception | E37: sensor.ppg_fault | F37: init_failed | G37: anomaly | H37: critical | I37: hr_err | J37: 200 | K37: Line present (boot sequence). | L37: The heart-rate sensor (GH3026) failed to initialise: no HR, HRV, SpO2 or sleep staging. | M37: 0 | N37: 0 | O37: =IF(ISNUMBER(N37),N37/'Critical Events Guide'!$D$18,"—") | P37: 0 | Q37: sensor_quality
A38: FW-35 | B38: P0 | C38: Sensors | D38: Exception | E38: sensor.ppg_fault | F38: config_switch_failed | G38: anomaly | H38: error | I38: YYT1 Error ! cfg%d switch fail !!!. YYT1 Error! uchArrayCfgIndex(%d) is invalid !!! | J38: 237, 238 | K38: Either line. Config index in properties. | L38: PPG register configuration could not be switched (e.g. HR to SpO2 mode), so that measurement fails. | M38: 0 | N38: 0 | O38: =IF(ISNUMBER(N38),N38/'Critical Events Guide'!$D$18,"—") | P38: 0 | Q38: sensor_quality
A39: FW-36 | B39: P0 | C39: Sensors | D39: Exception | E39: sensor.accel_fault | F39: init_failed | G39: anomaly | H39: critical | I39: gsensor init failed | J39: 202 | K39: Line present (boot sequence). | L39: The accelerometer failed to initialise: no steps, activity, sleep or auto-workout. | M39: 0 | N39: 0 | O39: =IF(ISNUMBER(N39),N39/'Critical Events Guide'!$D$18,"—") | P39: 0 | Q39: sensor_quality
A40: FW-37 | B40: P0 | C40: Sensors | D40: Exception | E40: sensor.temperature_fault | F40: init_failed | G40: anomaly | H40: error | I40: temp init faild, id %x | J40: 188 | K40: Line present (boot sequence). | L40: The skin-temperature sensor failed to initialise: no temperature trends. | M40: 0 | N40: 0 | O40: =IF(ISNUMBER(N40),N40/'Critical Events Guide'!$D$18,"—") | P40: 0 | Q40: sensor_quality
...

Sheet Ring Critical Events
A1: Ring (SDK) log: critical events to track
A2: From the ZHD SDK trace on iOS (ring-trace.log) and the ZH SDK BEHAVIOR log on Android (source = ring_log, domain = sdk unless the ring itself reports it). Red rows are where the SDK prints an error or a non-zero error code.
A3: # | B3: Priority | C3: Area | D3: Kind | E3: Event name | F3: Reason(s) | G3: Type | H3: Severity | I3: iOS ring log (ZHD SDK) | J3: Android ring log (ZH SDK) | K3: Command ID (Ring Logs sheets) | L3: Detection rule | M3: What it means / why track it | N3: iOS evidence (36 traces, 2026) | O3: Android evidence (13 days, 2026) | P3: Tag | Q3: Open question
A4: RL-01 | B4: P0 | C4: Connection | D4: Exception | E4: connection.abnormal_disconnect | F4: cb_6_timeout · cb_<code> · gatt_<status> | G4: anomaly | H4: warning | I4: <TL> [SDK][ConnectState] didDisconnectPeripheral [<device>]: 蓝牙断开 error:Error Domain=CBErrorDomain Code=6 "The connection has timed out unexpectedly." ZHDSDKErrorCode:305 errorDescription:… (state ZHDConnectStateFailconnected = 4) | J4: ----> sdk --- connectstate -----> Disconnected ----> sdk --- othercmd ---------> disconnect() isUser:false onConnectionStateChange status = <GATT status> | K4: 34 GetDeviceDisconnectReason | L4: Disconnect the app did not request (error present, isUser:false). Reason = CoreBluetooth error code (iOS) or GATT status (Android). Alert on the per-device daily rate. | M4: The link dropped. Normal when the phone is out of range, so only the rate matters. The app emits this event (App sheet); the ring log supplies the code, and the FW sheet's `ble.link_lost` the ring-side cause. | N4: CBError 6: 765 lines in 22 of 36 traces. `蓝牙断开 error:(null)`: 24 lines in 4 | O4: `Disconnected`: 308 lines on 11 of 13 days. `disconnect() isUser:false`: 10 | P4: ble_disconnect | Q4: Android calls getDisconnectReason() after reconnects, but every sample answered reason 0, and the band answers errorCode 1 (not supported). Is cmd 34 implemented on the ring?
A5: RL-02 | B5: P0 | C5: Connection | D5: Exception | E5: connection.failed | F5: pairing_info_removed · encryption_failed · connect_failed | G5: failure | H5: error | I5: <TL> [SDK][ConnectState] didFailToConnectPeripheral [<device>]: 蓝牙连接失败(<name>) error:Error Domain=CBErrorDomain Code=14 | 15 ZHDSDKErrorCode:306 后台模式下连接设备 配对信息被删除 停止重连 (bond deleted, reconnect stopped) | J5: ----> sdk --- connectstate -----> Failed Connect | K5: — | L5: Connection attempt ends in didFailToConnect. Reason from the CoreBluetooth code: 14 = the ring no longer has the bond, 15 = encryption timed out. | M5: The ring cannot reconnect. CB 14 is the classic "stopped connecting after a reset" ticket; the user must forget the ring in iOS Settings → Bluetooth. | N5: CB 14: 24 lines in 3 traces (incl. SDK 2.4.7, 14 Sep). CB 15: 24 in 2. ZHDSDKErrorCode 306: 32 in 4 | O5: See connection.reconnect_storm (`Failed Connect` is mostly out-of-range retries) | P5: ble_pairing
A6: RL-03 | B6: P0 | C6: Connection | D6: Exception | E6: connection.failed | F6: verification_failed | G6: failure | H6: error | I6: ZHDConnectStateVerfYFailed (5) [<device>]: 重连账号校验 :<SEVerifyResult …> (reconnect account check) bind_check_result: VERIFICATION_FAILED | J6: ----> sdk --- othercmd ---------> verifyUserId() <user id> — with no Connected after it | K6: 19 VerifyUserNumber | L6: Account verification on (re)connect fails. | M6: The ring holds a different user id, so the app can't use it until it is reset. The ring-side twin is `pairing.account_mismatch` in the FW sheet. | N6: VERIFICATION_FAILED: 5 lines in 3 traces (SUCCESS: 5 in 4) | O6: Not seen | P6: ble_pairing
A7: RL-04 | B7: P0 | C7: Connection | D7: Exception | E7: connection.failed | F7: notify_enable_failed | G7: failure | H7: error | I7: ZHDConnectStateNotificationFailed (14) protobuf%ld通知开启失败 (notification enable failed) 使能失败,%@ ZHDSDKErrorCode:308 连接成功返回2 超时 _findCharactCount:%d _findNotifyCount:%d | J7: enableNotification channel timeout ReadCharacteristicRunnable timeout | K7: — | L7: Notification enable fails or times out after the link is up. | M7: The link is up but the ring can't push data, so nothing syncs. PRD §7.3 reason (the partner's code 1314). | N7: Not seen (success line `protobuf通知开启成功`: 491 in 14 traces) | O7: Not seen | P7: ble_pairing
A8: RL-05 | B8: P0 | C8: Connection | D8: Context | E8: bluetooth.unavailable | F8: powered_off · unauthorized · unsupported | G8: context | H8: info | I8: [SYS][BluetoothState] CBManagerStatePoweredOff ZHDConnectStatePowerOff (9) / Unauthorized (10) / Unsupported (13) ZHDSDKErrorCode:303 蓝牙关闭 | J8: — (app-side only; see App sheet) | K8: — | L8: Bluetooth state change reported by the SDK. | M8: Explains every connection and sync failure that follows. Not a fault. | N8: PoweredOff: 2 traces. 303 蓝牙关闭: 4 lines in 2 | O8: — | P8: permissions
A9: RL-06 | B9: P1 | C9: Connection | D9: Derived | E9: connection.reconnect_storm | F9: service_discovery_timeout · connect_retries | G9: anomaly | H9: warning | I9: [<device>]: 设备连接后 发现服务超过5s,发起重新连接 (services not found within 5 s → reconnect) 自动重连设备调用-[ZHDInfoBlePeripheral autoConnectCheck] 开始自动重连timer | J9: ----> sdk --- connectstate -----> Connecting ----> sdk --- connectstate -----> Failed Connect (repeating, no Connected) | K9: — | L9: More than N connect attempts in an hour with no `Connected`, or `发现服务超过5s` more than N times in an hour. Tune N on real data. | M9: The phone keeps reconnecting without success: phone and ring battery drain and syncs never finish. | N9: `发现服务超过5s`: 4,960 lines in 5 traces, all SDK 2.2.3–2.3.1 (Mar–Apr). Not seen on 2.4.7 | O9: 15,939 `Connecting` and 2,949 `Failed Connect` against 232 `Connected` over 13 days | P9: ble_disconnect
A10: RL-07 | B10: P1 | C10: Connection | D10: Exception | E10: connection.failed | F10: reconnect_precondition · device_info_missing · uuid_changed · device_type_unsupported | G10: failure | H10: warning | I10: thorwErrcode code=301 开始自动重连条件不满足 (auto-reconnect preconditions not met) ZHDSDKErrorCode:300 / 302 / 304 | J10: — | K10: — | L10: SDK error 300, 301, 302 or 304. | M10: The SDK refuses to (re)connect before trying, usually because saved device info is stale after a ring reset (302 = UUID changed). | N10: `开始自动重连条件不满足`: 6 lines in 3 traces | O10: — | P10: ble_pairing
A11: RL-08 | B11: P1 | C11: Connection | D11: Context | E11: bluetooth.resetting | G11: context | H11: info | I11: [SYS][BluetoothState] CBManagerStateResetting ZHDConnectStateResetting (12) ZHDSDKErrorCode:303 蓝牙状态重置 | J11: — | K11: — | L11: SDK reports Resetting. | M11: The iOS Bluetooth stack restarted and every link dropped. | N11: 5 lines in 2 traces. 303 蓝牙状态重置: 10 in 2 | O11: — | P11: ble_disconnect
A12: RL-09 | B12: P0 | C12: Pairing | D12: Exception | E12: pairing.failed | F12: refused · timeout · verification_failed · already_bound · battery_low | G12: failure | H12: error | I12: [<device>]:发起配对 bindStatus :%d bind_check_result: <result> (ZHDBindCheckBindCheckResult 1 refuse · 2 overtime · 3 verification failed) 0-binding failed, 1-binding successful | J12: ----> sdk --- othercmd ---------> requestDeviceBindState() X-LOG: Exception = 02 02 (Binding / Failed) Bond on Error · Bond on failed | K12: 16 InquiryBindingStatus · 17 BindingCheck · 18 BindingResult · 21 RequestPairing · 22 RequestPairingResult | L12: Bind check result ≠ 0, or bind result = failed. The app emits the event (App sheet); the SDK result becomes the reason. | M12: The partner's highest-volume ticket class. The ring-side reason (not on the charger, key check failed) is `pairing.bind_rejected` in the FW sheet. | N12: VERIFICATION_FAILED: 5 lines in 3 traces | O12: `Exception = 02 02`: not seen | P12: ble_pairing
A13: RL-10 | B13: P0 | C13: Sync & commands | D13: Exception | E13: sync.failed | F13: daily_timeout · sport_timeout · total_timeout | G13: failure | H13: error | I13: ZHDSDKErrorCode:414 (daily data synchronization timeout!) · 413 (motion data) · 415 (total data) 日常同步超时 (daily sync timeout) ZHD113115TimeOut | J13: ----> sdk --- dailysync --------> progress:%d, totalProgress:%d — progress stops short of total, then Disconnected / Failed Connect | K13: 112 GetFitnessTypeIdList · 113 RequestFitnessTypeId · 115 ConfirmFitnessTypeId | L13: SDK reports a sync timeout, or Android daily-sync progress stops before totalProgress. | M13: The partner's most common error class: the day's data does not reach the phone. The app emits `sync.failed`; this gives the SDK reason. | N13: Not seen in traces (app log: `daily pull stalled` in 5 of 43 iOS app logs) | O13: Not measured | P13: sync_timeout
A14: RL-11 | B14: P0 | C14: Sync & commands | D14: Exception | E14: device.command_timeout | F14: <command name> | G14: exception | H14: warning | I14: [<device>]:removeFirstCommond 停止定时器 errorCode:401 (instruction timed out, removed) ZHDSDKErrorCode:406 (device return timeout) · 408 (send timeout) · 410 (resend timeout) [<device>]: 传输超时 · 当前发送进度 超时 | J14: ReadCharacteristicRunnable timeout PROTOBUF_%d write = … failNum = %d | K14: Any (reason = command name from the Ring Logs sheets) | L14: A command removed with error 401, 406, 408 or 410. If it happens inside a sync, report it as that sync's failure reason instead (EVT-8). | M14: The ring stopped answering a specific command, which tells firmware which handler hangs. | N14: errorCode 401: 3 lines in 3 traces (8,422 other removals had code 0) | O14: `failNum = 3`: 3 lines in 1 file | P14: sync_timeout
A15: RL-12 | B15: P1 | C15: Sync & commands | D15: Exception | E15: device.command_rejected | F15: <command>_<code> | G15: exception | H15: warning | I15: [<device>]: <command> SEErrorCode:%d (non-zero) [<device>]: 收到设备不支持指令 id:%d SEErrorCode:%d (device does not support command) — except `确认日常数据收到 SEErrorCode:%d`, which prints the data type, not an error | J15: parsing id = %s = %d --> <COMMAND> errorCode = %d (non-zero) | K15: Any | L15: Command response with a non-zero error code. Reason = command name + code. | M15: The ring refused a command (often one a band model doesn't support), so a setting or feature silently does not work. | N15: No non-zero codes in 36 traces | O15: errorCode 1 on SET_AUTOMATIC_MOTION_RECOGNITION_SETTING, SET_PRESSURE_MODE and GET_DEVICE_DISCONNECT_REASON (band, 1 file); 166 other responses were 0 | P15: firmware_cmd_error | Q15: Share the SEErrorCode value list.
A16: RL-13 | B16: P1 | C16: Sync & commands | D16: Exception | E16: device.time_set_failed | F16: error_<code> | G16: exception | H16: warning | I16: [<device>]:设置系统时间 SEErrorCode :%d (non-zero) | J16: ----> sdk --- othercmd ---------> setTime() currentTimeMillis:%d parsing id = … --> SET_SYSTEM_TIME errorCode = %d | K16: 48 SetSystemTime | L16: Set-time response with a non-zero code. | M16: The ring clock stays wrong, so data is mis-dated (see `device.clock_reset` in the FW sheet). The iOS app carries on syncing after this, so it is not a sync failure. | N16: 235 set-time responses in 31 traces, all 0 | O16: All 0 | P16: time_zone
A17: RL-14 | B17: P1 | C17: Sync & commands | D17: Exception | E17: sync.parse_failed | F17: decompression_failed · wear_data_error · abnormal_version | G17: exception | H17: warning | I17: internal error - decompression failed: %d · lzo_init() failed !!! ZHDProtobufNewRes || 接受解析数据 wear error %@ (parse error) 收到异常的版本号 (abnormal version number received) | J17: — (LZO / CRC utilities log nothing) | K17: — | L17: Any of these lines. | M17: Data reached the phone but could not be decoded, so that block is lost or pulled again. | N17: Not seen | O17: — | P17: sync_partial | Q17: Can the Android SDK log CRC and decompression failures?
A18: RL-15 | B18: P1 | C18: Sync & commands | D18: Exception | E18: sdk.send_failed | F18: not_connected · notification_not_enabled · target_empty · write_error | G18: exception | H18: warning | I18: ZHDSDKErrorCode:404 (Bluetooth is not connected when sending data) · 417 (not enabled when sending) · 402 (target empty) · 403 · 307 (APP failed to write to Bluetooth device) | J18: PROTOBUF_%d write = … failNum = %d | K18: Any | L18: SDK error 402, 403, 404, 307 or 417 on send. | M18: The app talked to a ring that wasn't ready: usually a state bug in the app's connection handling. | N18: Not seen | O18: `failNum = 3`: 3 lines in 1 file | P18: ble_disconnect
A19: RL-16 | B19: P0 | C19: Device reports | D19: Exception | E19: device.overheat | F19: <event> · <protect_level> | G19: anomaly | H19: critical | I19: SDK callback for ReportDeviceTemperatureEvent (no log text found) | J19: SDK callback for REPORT_DEVICE_TEMPERATURE_EVENT (no log text found) | K19: 771 ReportDeviceTemperatureEvent · 770 ConfireDeviceTemperatureEvent | L19: Ring pushes a temperature event. Emit once from this real-time report; the firmware line (FW sheet) confirms it a day later. | M19: Temperature protection switched ring functions off. Safety-relevant. | N19: Not seen | O19: Not seen | P19: other | Q19: Event values and protect levels.
A20: RL-17 | B20: P0 | C20: Device reports | D20: Derived | E20: battery.sudden_drop | G20: anomaly | H20: error | I20: [<device>]:设备电池信息 result :%@ (battery info) | J20: ----> sdk --- powerstate -------> battery:%d，Status:%d | K20: 33 GetDeviceBatteryStatus · 37 DeviceBatteryValueRequest | L20: Battery falls 15 points or more within 2 hours without charging (charge status 1 charging · 2 not charging · 3 full). Emit from this real-time source; the FW sheet rule is the fallback. | M20: PRD §7.4 (unblocked). Arrives the same day, unlike firmware logs. | N20: Not measured | O20: `powerstate`: 5,878 readings on 12 of 13 days | P20: battery
A21: RL-18 | B21: P1 | C21: Device reports | D21: Derived | E21: battery.charge_fault | F21: flapping · stuck_not_full | G21: anomaly | H21: warning | I21: [<device>]:设备电池信息 result :%@ (charge status) | J21: ----> sdk --- powerstate -------> battery:%d，Status:%d | K21: 33 GetDeviceBatteryStatus · 37 DeviceBatteryValueRequest | L21: Charge status flips 6 or more times in 10 minutes, or stays "charging" at 99% for over 30 minutes. | M21: Poor charger contact or a charging-IC fault, seen the same day. | N21: Not measured | O21: Not measured | P21: battery
A22: RL-19 | B22: P1 | C22: Device reports | D22: Exception | E22: battery.fault | F22: nfc_sleep_abnormal | G22: anomaly | H22: error | I22: SDK callback for RequestNfcSleepErr (no log text found) | J22: onNfcSleepErr %d · RealTimeBean NFC Sleep Err %d (app log) | K22: 419 RequestNfcSleepErr | L22: Value ≠ 0. | M22: Real-time report of the NFC / wireless-charging sleep error. The FW sheet's `Err: nfc sleep abnormal` is the delayed version. | N22: Not logged | O22: `onNfcSleepErr 0`: 174 lines in 14 of 16 files (2025), never non-zero | P22: battery | Q22: What do non-zero values mean?
A23: RL-20 | B23: P1 | C23: Device reports | D23: Exception | E23: measurement.failed | F23: error_reason_<n> · not_worn | G23: exception | H23: warning | I23: [<device>]: 戒指开始测量 SEWear_SEFunctionId_RingStartMessage SEErrorCode:%d [<device>]: 戒指手动结束测量 SEErrorCode:%d error_reason: %d | J23: onMeasureResult {"errorReason":%d,"isWrist":%b,…} | K23: 105–109 Message* · 358–362 Wear* | L23: Spot measurement ends with errorReason ≠ 0 or isWrist = false. | M23: The user tapped measure and got nothing: directly visible. | N23: error_reason 2: 2 lines in 1 trace | O23: errorReason 2: 1 (2025) | P23: sensor_quality | Q23: List errorReason values.
A24: RL-21 | B24: P2 | C24: Device reports | D24: Context | E24: device.idle_reboot_requested | G24: context | H24: info | I24: SDK callback for DeviceIdleRebootRequest (no log text found) | J24: SDK callback for DEVICE_IDLE_REBOOT_REQUEST (no log text found) | K24: 776 DeviceIdleRebootRequest · 777 DeviceIdleRebootRespond | L24: Ring asks before an idle reboot. | M24: Pairs with the firmware's `sys idle reboot`, so a planned reboot isn't mistaken for a crash. | N24: Not seen | O24: Not seen | P24: firmware_reboot
A25: RL-22 | B25: P1 | C25: Log transfer | D25: Exception | E25: log.firmware_fetch_failed | F25: no_log · transfer_timeout · error_<code> | G25: exception | H25: warning | I25: [<device>]: app开始设备debug日志上传SEWear_SEFunctionId_PhoneRequestFileInfoUpdate SEErrorCode:%d 获取指定LOG文件是否有数据结果:%@ (log file has data?) 发送 LOG文件发送控制 结果:%ld ZHDSDKErrorCode:500 (large file timeout) | J25: GetFirmwareLogs dispatch failed (FeedbackSubmitWorker, logcat only) | K25: 4101 PhoneRequestLogUpdate · 4102 WearSendLogState (0 start · 1 stop · 2 no data) · 4109 PhoneRequestFileInfoUpdate | L25: Non-zero code, `no data` (2), or a large-file timeout while pulling the firmware log. | M25: The firmware dump didn't arrive, so every FW-sheet rule is blind for that ring that day. | N25: 20 requests in 7 traces, all code 0 | O25: Not measured | P25: data_gap
A26: RL-23 | B26: P2 | C26: Log transfer | D26: Exception | E26: connection.mtu_error | F26: mtu_out_of_limit · mtu_config_empty | G26: exception | H26: warning | I26: ZHDSDKErrorCode:412 (mtu < 20 || mtu > 1000) · 101 (device mtu config empty) | J26: ----> sdk --- othercmd ---------> nativeMethodGetMtu() | K26: 0 MtuRequestChange | L26: SDK error 412 or 101. | M26: A bad MTU makes transfers slow or fail. | N26: Not seen | O26: Not seen | P26: ble_disconnect

Sheet App Critical Events
A1: App log: critical events to track
A2: Emitted by the app at the call site (source = app). iOS paths are relative to noisefit-ios-luna/Luna/Luna/. Android: luna/ = app/src/main/java/com/noisefit/luna/, app/ = app/src/main/java/com/, zhsdk/ = noisefit_zh_sdk/src/main/java/com/noisefit_zhsdk/, commons/ = commons/src/main/java/com/noisefit_commans/. "(logcat only)" = not in the uploaded log today.
A3: # | B3: Priority | C3: Area | D3: Kind | E3: Event name | F3: Reason(s) | G3: Type | H3: Tracked operation | I3: Severity | J3: iOS log line · source | K3: Android log line · source | L3: Emit when | M3: What it means / why track it | N3: iOS evidence (43 app logs, 2026) | O3: Android evidence (17 app logs) | P3: Tag | Q3: Notes
A4: APP-01 | B4: P0 | C4: Connection | D4: Exception | E4: connection.failed | F4: not_found · verification_timeout · pairing_info_lost · uuid_changed · unsupported_device · handshake_disconnect · timeout · generic | G4: failure | H4: connection | I4: error | J4: WearableService ← failed to connect: reason={reason} rawError={rawError} BLE/Service/WearableService.swift:2088 WearableService → locate timed out for uuid={uuid} — clearing :1624 WearableService → verification timed out for uuid={uuid} after {n}s — failing the attempt :1670 WearableService ← disconnect during handshake for {deviceName} — treating as connection failure :2128 | K4: CONNECT_DEADLINE fired after {ms}ms → surfacing Disconnected luna/ui/MainViewModel.kt:1398 ZhConnectHandler :onConnectState TimeOut zhsdk/handler/ZhConnectHandler.kt:121 X-LOG: Exception = 01 02 (+ Comment : STATE_DISCONNECTED) ZhConnectHandler.kt:164, 173, 299 | L4: A connection attempt ends without reaching connected. Reason from WearableConnectionFailureReason and the CoreBluetooth code (iOS), or timeout / disconnect (Android). | M4: Core flow: nothing syncs without a connection. Failure rate per attempt is the headline connection metric. | N4: `locate timed out`: 69 lines in 17 of 43 logs. `failed to connect`: 15 in 6 (pairingInfoLost: 4 in 2) | O4: `onConnectState TimeOut`: 100 lines in 3 of 16 files (2025). `01 02`: 5 in 1 | P4: ble_disconnect | Q4: Android `Exception = 01 FF` is NOT a failure: it is the Connect / Other lifecycle marker (Connect, Connected, Initialized, Release). Do not map it to an exception event.
A5: APP-02 | B5: P0 | C5: Connection | D5: Exception | E5: connection.abnormal_disconnect | F5: cb_<code> · gatt_<status> | G5: anomaly | I5: warning | J5: WearableService ← disconnected: {deviceName} error={error.localizedDescription} BLE/Service/WearableService.swift:2142 BG: disconnected {deviceName} — rawError={domain}#{code} :2143 | K5: ZhConnectHandler :onConnectState disconnected zhsdk/handler/ZhConnectHandler.kt:131 disconnection reason … reason: {lastDisconnectReason} ZhConnectHandler.kt:199 | L5: The link drops while connected and the app did not ask for it (error present). Alert on the per-device daily rate. | M5: PRD §7.3. A spike after a release is a link regression. The Ring sheet gives the SDK code and the FW sheet the ring-side cause. | N5: `disconnected … timed out unexpectedly`: 167 lines in 27 of 43 logs | O5: `onConnectState disconnected`: 296 lines in 16 of 16 files (2025); disconnect reason always 0 | P5: ble_disconnect
A6: APP-03 | B6: P0 | C6: Connection | D6: Context | E6: bluetooth.unavailable | F6: powered_off · unauthorized · unsupported | G6: context | I6: info | J6: DeviceSystemPromptPresenter → bluetooth-off sheet App/DeviceSystemPromptPresenter.swift:152 WorkoutService → checkStartReadiness: bluetooth unavailable ({state}) Modules/Workout/Service/WorkoutService.swift:1291 | K6: startScan: bluetoothLeScanner is null (BT off?) luna/ui/MainViewModel.kt:1699 (logcat only) | L6: Bluetooth becomes unavailable (WearableBluetoothState.isUnavailable on iOS). | M6: Explains the connection and sync failures that follow. PRD §7.3. | N6: bluetooth-off sheet: 1 log | O6: Logcat only | P6: permissions
A7: APP-04 | B7: P1 | C7: Connection | D7: Context | E7: connection.user_action_required | F7: requires_reset · requires_pairing · pairing_info_lost · uuid_changed | G7: context | I7: warning | J7: ConnectionAlertPresenter → requiresReset({device.name}) · → pairingInfoLost · → uuidChanged · → requiresPairing({device.name}) App/ConnectionAlertPresenter.swift:113–137 | K7: — (no log line) | L7: The app shows an alert telling the user to reset, forget or re-pair the ring. | M7: The moment a user is stranded. A jump after a release means users are being pushed into re-setup. | N7: 2 lines in 1 of 43 logs | O7: — | P7: ble_pairing
A8: APP-05 | B8: P0 | C8: Pairing | D8: Exception | E8: pairing.failed | F8: device_rejected · timeout · verification_failed · already_bound_to_other_user · bluetooth_disconnected · device_battery_low · empty_device_number · reacquire_timeout · bond_failed | G8: failure | H8: pairing | I8: error | J8: WearablePairingService ← startBinding error: {description} code={errorCode} → {reason} BLE/Service/WearablePairingService.swift:137 ← binding status query error: {description} code={errorCode} :87 ← binding check SUCCESS but deviceNumber empty (stacked ceremony?) — treating as failure :112 WearableService ← pairing failed: device bound to another user — requiresReset BLE/Service/WearableService.swift:2343 PairingFlowViewModel ← post-reset re-acquire timed out — showing forget-bond instruction Modules/Device/ViewModel/PairingFlowViewModel.swift:608 | K8: PAIR_TIMEOUT fired after {ms}ms → Pairing unsuccessful luna/ui/MainViewModel.kt:1295 PAIR_RETRY {n}/{max} after ConnectFailed({status}) MainViewModel.kt:4139 X-LOG: Exception = 02 02 (Binding / Failed) zhsdk/handler/ZhConnectHandler.kt:364 Bond on Error · Bond on failed ZhConnectHandler.kt:557, 568 | L8: Pairing ends without a bound ring. Reason from WearablePairingFailureReason (iOS) or timeout / bond failure (Android). | M8: The partner's highest-volume ticket class. The FW sheet adds the ring-side reason (not on the charger, key check failed). | N8: `binding check VERIFICATION FAILED`: 6 lines in 4 of 43 logs | O8: Not seen | P8: ble_pairing
A9: APP-06 | B9: P1 | C9: Pairing | D9: Exception | E9: device.unbind_failed | F9: sdk_error_<code> · factory_reset_error | G9: exception | I9: warning | J9: WearableService ← unpair error: {description} code={errorCode} BLE/Service/WearableService.swift:900 ← factoryReset unbind error: {description} code={errorCode} :1302 ← factoryResetTargeting unbind error: {description} code={errorCode} :1916 | K9: — (no log line) | L9: Unbind or factory reset returns an SDK error. | M9: The user removed the ring in the app but the ring still holds the bond, so the next pairing fails with "already bound". | N9: Not seen | O9: — | P9: ble_pairing | Q9: Android: add a log / event at unbind.
A10: APP-07 | B10: P1 | C10: Pairing | D10: Exception | E10: device.registration_failed | F10: network · server_<status> · no_mac · device_id_unresolved | G10: exception | I10: error | J10: RingRegistrationService ← device registration failed: {error} — will retry on the next trigger BLE/Service/RingRegistrationService.swift:330 → no MAC resolvable for the current device — registration deferred :260 | K10: RingRegister NetworkError code=%d %s luna/ui/MainViewModel.kt:2289 (logcat only) Aborting POST — device_id unresolved … MainViewModel.kt:2217 (logcat only) | L10: Registering the paired ring with the server fails. | M10: The ring is paired on the phone but unknown to the server: firmware update checks and support look-ups break. | N10: 1 line in 1 of 43 logs | O10: Logcat only | P10: api_error_5xx
